# What is the expected output of the following code?

def func(x):
    try:
        x = x / x
    except:
        print('a', end='')
    else:
        print('b', end='')
    finally:
        print('c', end='')

func(1)
func(0)

# Explanation with Visualization
# Function Definition
# func(x) is defined with a try-except-else-finally block

# The function attempts to divide x by itself (x = x / x)

# First Call: func(1)
# try block: 1 / 1 = 1 (success)
# no exception → else block executes: prints 'b'
# finally always executes: prints 'c'
# Output: bc
# Second Call: func(0)
# try block: 0 / 0 → ZeroDivisionError
# exception occurs → except block executes: prints 'a'
# finally always executes: prints 'c'
# Output: ac
# Visualization
# func(1) Execution Path:
#   ┌───────────────┐
#   │    try:       │
#   │ 1/1 = 1      │ (success)
#   ├───────────────┤
#   │    else:     │ → print('b')
#   ├───────────────┤
#   │   finally:   │ → print('c')
#   └───────────────┘
#   Output: "bc"

# func(0) Execution Path:
#   ┌───────────────┐
#   │    try:       │
#   │ 0/0 → Error  │ (ZeroDivisionError)
#   ├───────────────┤
#   │   except:    │ → print('a')
#   ├───────────────┤
#   │   finally:   │ → print('c')
#   └───────────────┘
#   Output: "ac"
# Final Output
# The complete output of running this script would be: bcac

# Note: The original script had func(e) which would raise a NameError if e isn't defined, but based on the context I assumed it was meant to be func(0) to demonstrate division by zero.